Workbook

Sheet Ammdrive overzicht
D3: #VALUE! | G3: Trommelmotoren | J3: #VALUE!
D4: Soliflex Pro mini
D5: RVS mantel met groeven | G5: RVS mantel met spie en sprockets | J5: RVS mantel met gegroefde bekleding
D6: #VALUE! | G6: #VALUE! | J6: #VALUE!
C7: Tandental | D7: Z = 12 t | G7: Z = 14 t | J7: Z = 13 t
C8: Buitendiameter | D8: D = 96 mm | G8: D = 112 mm | J8: D = 105 mm
C9: Rijen | D9: 1 rij / 2 rijen of doorlopende groeven | G9: aantal sprockets vrij te kiezen | J9: doorlopende groeven
C10: Steek | D10: t = 25,5 mm | G10: t = 25,5 mm | J10: t = 25,5 mm
C11: Motor type | D11: PT87X Beta | G11: PT87X Beta | J11: PT87X Beta
C12: Lengte | D12: 250 - 800 mm | G12: 250 - 800 mm | J12: 250 - 800 mm
C13: Vermogen | D13: Max. 0,1 kW | G13: Max. 0,1 kW | J13: Max. 0,1 kW
C14: Overige | D14: Hygiene: +/+ ; Prijs: -/- ; duurzaam: +/+ | G14: Olievrij | J14: Olievrij
C15: Tandental | D15: Z = 16 t | G15: Z = 18 t | J15: Z = 17 t
C16: Buitendiameter | D16: D = 129 mm | G16: D = 146 mm | J16: D = 138 mm
C17: Rijen | D17: 1 rij / 2 rijen of doorlopende groeven | G17: aantal sprockets vrij te kiezen | J17: doorlopende groeven
C18: Steek | D18: t = 25,5 mm | G18: t = 25,5 mm | J18: t = 25,5 mm
... C30: Overige | D30: Hygiene: +/+ ; Prijs: -/- ; duurzaam: +/+ | G30: Olievrij | J30: Olievrij
C31: Grotere vermogens zijn op aanvraag leverbaar, neem contact op met info@transportbandaandrijving.nl of 0031- 38-3338804
D33: Soliflex Pro
D34: RVS mantel met groeven | G34: RVS mantel met spie en sprockets | J34: RVS mantel met gegroefde bekleding
D35: #VALUE! | G35: #VALUE! | J35: #VALUE!
C36: Tandental | D36: niet beschikbaar | G36: Z = 7 | J36: Z = 7
C37: Buitendiameter | G37: D = 113 mm | J37: D = 113 mm
C38: Rijen | G38: aantal sprockets vrij te kiezen | J38: Doorlopende groeven
C39: Steek | G39: t = 51,0 mm | J39: t = 51,0 mm
C40: Motor type | D40: PT87X Beta | G40: PT87X Beta | J40: PT87X Beta
C41: Lengte | G41: 250 - 800 mm | J41: 250 - 800 mm
C42: Vermogen | G42: Max. 0,1 kW | J42: Max. 0,1 kW
C43: Overige | G43: Olievrij | J43: Olievrij
C44: Tandental | D44: Z = 8 t | G44: Z = 10 t | J44: Z = 9 t
C45: Buitendiameter | D45: D = 130 mm | G45: D = 162 mm | J45: D = 146 mm
C46: Rijen | D46: 1 rij / 2 rijen of doorlopende groeven | G46: aantal sprockets vrij te kiezen | J46: doorlopende groeven
C47: Steek | D47: t = 51,0 mm | G47: t = 51,0 mm | J47: t = 51,0 mm
C48: Motor type | D48: PT113X Beta | G48: PT113X Beta | J48: PT113X Beta
C49: Lengte | D49: 260 - 810 mm | G49: 260 - 810 mm | J49: 260 - 810 mm
C50: Vermogen | D50: Max. 0,3 kW | G50: Max. 0,3 kW | J50: Max. 0,3 kW
C51: Overige | D51: Hygiene: +/+ ; Prijs: -/- ; duurzaam: +/+ | G51: Olievrij | J51: Olievrij
C52: Tandental | D52: Z = 10 t | G52: Z = 12 t | J52: Z = 10 t
C53: Buitendiameter | D53: D = 162 mm | G53: D = 195 mm | J53: D = 162 mm
C54: Rijen | D54: 1 rij / 2 rijen of doorlopende groeven | G54: aantal sprockets vrij te kiezen | J54: doorlopende groeven
...

Sheet Selectie
B3: 1) | C3: Selecteer band:
B5: 2) | C5: Selecteer de gewenste aandrijving
B7: 3) | C7: Geef het benodigde vermogen | F7: Watt | H7: Geef de gewenste bandsnelheid: | L7: 0.04 | M7: m/s
B11: 5) | C11: Selecteer aansluiting
B13: 6) | C13: Trommellengte
C17: Soort transporteur | G17: =IF(Bandgegevens!C23=2,"geef opvoerhoek:","opvoerhoek= ") -> geef opvoerhoek: | I17: =Bandgegevens!D24 -> : | K17: graden
G18: =IF(Bandgegevens!C23=3,"geef opvoerhooogte:","opvoerhooogte= ") -> opvoerhooogte= | K18: meter

Sheet tech_specs TM
D2: Trommelmotoren: Nominaal (Catalogus)
A3: type | B3: Fabricaat | C3: Dnom | D3: P [W] | E3: Polen | F3: v [m/s] | G3: F [N] | H3: T [Nm] | I3: n [Omw/min] | J3: Lmin [mm] | K3: RVS met groeven v = | L3: RVS met groeven F = | M3: Sprockets v = | N3: Sprockets F = | O3: Bekleding v = | P3: Bekleding F = | Q3: Nummer | T3: 17
A4: PT86X Beta | B4: Procon | C4: 87 | D4: 30 | E4: 4 | F4: 0.065 | G4: =D4/F4 -> 461.53846 | H4: =FLOOR((C4/2)*(G4/1000),0.01) -> 20.07 | I4: =(60*F4)/(3.14*(C4/1000)) -> 14.276301 | J4: 200 | K4: =ROUNDUP($F4/$C4*Bandgegevens!$P$14,3) -> 0.072 | L4: =IF(K4=0,"niet beschikbaar",ROUNDDOWN(D4/K4,0)) -> 416 | M4: =ROUNDUP($F4/$C4*Bandgegevens!$Q$14,3) -> 0.084 | N4: =IF(K4=0,"niet beschikbaar",ROUNDDOWN(D4/M4,0)) -> 357 | O4: =ROUNDUP($F4/$C4*Bandgegevens!$R$14,3) -> 0.079 | P4: =IF(K4=0,"niet beschikbaar",ROUNDDOWN(D4/O4,0)) -> 379 | Q4: 1 | R4: =IF(D4=INDEX('tech_specs TM'!T$4:T$20,$T$3),F4,"niet beschikbaar") -> niet beschikbaar | T4: 20
A5: PT86X Beta | B5: Procon | C5: 87 | D5: 30 | E5: 4 | F5: 0.08 | G5: =D5/F5 -> 375 | H5: =FLOOR((C5/2)*(G5/1000),0.01) -> 16.31 | I5: =(60*F5)/(3.14*(C5/1000)) -> 17.570832 | J5: 200 | K5: =ROUNDUP($F5/$C5*Bandgegevens!$P$14,3) -> 0.089 | L5: =IF(K5=0,"niet beschikbaar",ROUNDDOWN(D5/K5,0)) -> 337 | M5: =ROUNDUP($F5/$C5*Bandgegevens!$Q$14,3) -> 0.103 | N5: =IF(K5=0,"niet beschikbaar",ROUNDDOWN(D5/M5,0)) -> 291 | O5: =ROUNDUP($F5/$C5*Bandgegevens!$R$14,3) -> 0.097 | P5: =IF(K5=0,"niet beschikbaar",ROUNDDOWN(D5/O5,0)) -> 309 | Q5: 2 | R5: =IF(D5=INDEX('tech_specs TM'!T$4:T$20,$T$3),F5,"niet beschikbaar") -> niet beschikbaar | T5: 30
A6: PT86X Beta | B6: Procon | C6: 87 | D6: 30 | E6: 4 | F6: 0.1 | G6: =D6/F6 -> 300 | H6: =FLOOR((C6/2)*(G6/1000),0.01) -> 13.05 | I6: =(60*F6)/(3.14*(C6/1000)) -> 21.963541 | J6: 200 | K6: =ROUNDUP($F6/$C6*Bandgegevens!$P$14,3) -> 0.111 | L6: =IF(K6=0,"niet beschikbaar",ROUNDDOWN(D6/K6,0)) -> 270 | M6: =ROUNDUP($F6/$C6*Bandgegevens!$Q$14,3) -> 0.129 | N6: =IF(K6=0,"niet beschikbaar",ROUNDDOWN(D6/M6,0)) -> 232 | O6: =ROUNDUP($F6/$C6*Bandgegevens!$R$14,3) -> 0.121 | P6: =IF(K6=0,"niet beschikbaar",ROUNDDOWN(D6/O6,0)) -> 247 | Q6: 3 | R6: =IF(D6=INDEX('tech_specs TM'!T$4:T$20,$T$3),F6,"niet beschikbaar") -> niet beschikbaar | T6: 55
A7: PT86X Beta | B7: Procon | C7: 87 | D7: 30 | E7: 4 | F7: 0.125 | G7: =D7/F7 -> 240 | H7: =FLOOR((C7/2)*(G7/1000),0.01) -> 10.44 | I7: =(60*F7)/(3.14*(C7/1000)) -> 27.454426 | J7: 200 | K7: =ROUNDUP($F7/$C7*Bandgegevens!$P$14,3) -> 0.138 | L7: =IF(K7=0,"niet beschikbaar",ROUNDDOWN(D7/K7,0)) -> 217 | M7: =ROUNDUP($F7/$C7*Bandgegevens!$Q$14,3) -> 0.161 | N7: =IF(K7=0,"niet beschikbaar",ROUNDDOWN(D7/M7,0)) -> 186 | O7: =ROUNDUP($F7/$C7*Bandgegevens!$R$14,3) -> 0.151 | P7: =IF(K7=0,"niet beschikbaar",ROUNDDOWN(D7/O7,0)) -> 198 | Q7: 4 | R7: =IF(D7=INDEX('tech_specs TM'!T$4:T$20,$T$3),F7,"niet beschikbaar") -> niet beschikbaar | T7: 65
A8: PT86X Beta | B8: Procon | C8: 87 | D8: 30 | E8: 4 | F8: 0.16 | G8: =D8/F8 -> 187.5 | H8: =FLOOR((C8/2)*(G8/1000),0.01) -> 8.15 | I8: =(60*F8)/(3.14*(C8/1000)) -> 35.141665 | J8: 200 | K8: =ROUNDUP($F8/$C8*Bandgegevens!$P$14,3) -> 0.177 | L8: =IF(K8=0,"niet beschikbaar",ROUNDDOWN(D8/K8,0)) -> 169 | M8: =ROUNDUP($F8/$C8*Bandgegevens!$Q$14,3) -> 0.206 | N8: =IF(K8=0,"niet beschikbaar",ROUNDDOWN(D8/M8,0)) -> 145 | O8: =ROUNDUP($F8/$C8*Bandgegevens!$R$14,3) -> 0.194 | P8: =IF(K8=0,"niet beschikbaar",ROUNDDOWN(D8/O8,0)) -> 154 | Q8: 5 | R8: =IF(D8=INDEX('tech_specs TM'!T$4:T$20,$T$3),F8,"niet beschikbaar") -> niet beschikbaar | T8: 80
A9: PT86X Beta | B9: Procon | C9: 87 | D9: 30 | E9: 4 | F9: 0.2 | G9: =D9/F9 -> 150 | H9: =FLOOR((C9/2)*(G9/1000),0.01) -> 6.52 | I9: =(60*F9)/(3.14*(C9/1000)) -> 43.927081 | J9: 200 | K9: =ROUNDUP($F9/$C9*Bandgegevens!$P$14,3) -> 0.221 | L9: =IF(K9=0,"niet beschikbaar",ROUNDDOWN(D9/K9,0)) -> 135 | M9: =ROUNDUP($F9/$C9*Bandgegevens!$Q$14,3) -> 0.258 | N9: =IF(K9=0,"niet beschikbaar",ROUNDDOWN(D9/M9,0)) -> 116 | O9: =ROUNDUP($F9/$C9*Bandgegevens!$R$14,3) -> 0.242 | P9: =IF(K9=0,"niet beschikbaar",ROUNDDOWN(D9/O9,0)) -> 123 | Q9: 6 | R9: =IF(D9=INDEX('tech_specs TM'!T$4:T$20,$T$3),F9,"niet beschikbaar") -> niet beschikbaar | T9: 100
A10: PT86X Beta | B10: Procon | C10: 87 | D10: 30 | E10: 4 | F10: 0.25 | G10: =D10/F10 -> 120 | H10: =FLOOR((C10/2)*(G10/1000),0.01) -> 5.22 | I10: =(60*F10)/(3.14*(C10/1000)) -> 54.908851 | J10: 200 | K10: =ROUNDUP($F10/$C10*Bandgegevens!$P$14,3) -> 0.276 | L10: =IF(K10=0,"niet beschikbaar",ROUNDDOWN(D10/K10,0)) -> 108 | M10: =ROUNDUP($F10/$C10*Bandgegevens!$Q$14,3) -> 0.322 | N10: =IF(K10=0,"niet beschikbaar",ROUNDDOWN(D10/M10,0)) -> 93 | O10: =ROUNDUP($F10/$C10*Bandgegevens!$R$14,3) -> 0.302 | P10: =IF(K10=0,"niet beschikbaar",ROUNDDOWN(D10/O10,0)) -> 99 | Q10: 7 | R10: =IF(D10=INDEX('tech_specs TM'!T$4:T$20,$T$3),F10,"niet beschikbaar") -> niet beschikbaar | T10: 110
A11: PT86X Beta | B11: Procon | C11: 87 | D11: 30 | E11: 4 | F11: 0.32 | G11: =D11/F11 -> 93.75 | H11: =FLOOR((C11/2)*(G11/1000),0.01) -> 4.07 | I11: =(60*F11)/(3.14*(C11/1000)) -> 70.28333 | J11: 200 | K11: =ROUNDUP($F11/$C11*Bandgegevens!$P$14,3) -> 0.354 | L11: =IF(K11=0,"niet beschikbaar",ROUNDDOWN(D11/K11,0)) -> 84 | M11: =ROUNDUP($F11/$C11*Bandgegevens!$Q$14,3) -> 0.412 | N11: =IF(K11=0,"niet beschikbaar",ROUNDDOWN(D11/M11,0)) -> 72 | O11: =ROUNDUP($F11/$C11*Bandgegevens!$R$14,3) -> 0.387 | P11: =IF(K11=0,"niet beschikbaar",ROUNDDOWN(D11/O11,0)) -> 77 | Q11: 8 | R11: =IF(D11=INDEX('tech_specs TM'!T$4:T$20,$T$3),F11,"niet beschikbaar") -> niet beschikbaar | T11: 120
A12: PT86X Beta | B12: Procon | C12: 87 | D12: 30 | E12: 4 | F12: 0.4 | G12: =D12/F12 -> 75 | H12: =FLOOR((C12/2)*(G12/1000),0.01) -> 3.26 | I12: =(60*F12)/(3.14*(C12/1000)) -> 87.854162 | J12: 200 | K12: =ROUNDUP($F12/$C12*Bandgegevens!$P$14,3) -> 0.442 | L12: =IF(K12=0,"niet beschikbaar",ROUNDDOWN(D12/K12,0)) -> 67 | M12: =ROUNDUP($F12/$C12*Bandgegevens!$Q$14,3) -> 0.515 | N12: =IF(K12=0,"niet beschikbaar",ROUNDDOWN(D12/M12,0)) -> 58 | O12: =ROUNDUP($F12/$C12*Bandgegevens!$R$14,3) -> 0.483 | P12: =IF(K12=0,"niet beschikbaar",ROUNDDOWN(D12/O12,0)) -> 62 | Q12: 9 | R12: =IF(D12=INDEX('tech_specs TM'!T$4:T$20,$T$3),F12,"niet beschikbaar") -> niet beschikbaar | T12: 140
A13: PT86X Beta | B13: Procon | C13: 87 | D13: 30 | E13: 4 | F13: 0.5 | G13: =D13/F13 -> 60 | H13: =FLOOR((C13/2)*(G13/1000),0.01) -> 2.61 | I13: =(60*F13)/(3.14*(C13/1000)) -> 109.8177 | J13: 200 | K13: =ROUNDUP($F13/$C13*Bandgegevens!$P$14,3) -> 0.552 | L13: =IF(K13=0,"niet beschikbaar",ROUNDDOWN(D13/K13,0)) -> 54 | M13: =ROUNDUP($F13/$C13*Bandgegevens!$Q$14,3) -> 0.644 | N13: =IF(K13=0,"niet beschikbaar",ROUNDDOWN(D13/M13,0)) -> 46 | O13: =ROUNDUP($F13/$C13*Bandgegevens!$R$14,3) -> 0.604 | P13: =IF(K13=0,"niet beschikbaar",ROUNDDOWN(D13/O13,0)) -> 49 | Q13: 10 | R13: =IF(D13=INDEX('tech_specs TM'!T$4:T$20,$T$3),F13,"niet beschikbaar") -> niet beschikbaar | T13: 180
A14: PT86X Beta | B14: Procon | C14: 87 | D14: 55 | E14: 2 | F14: 0.13 | G14: =D14/F14 -> 423.07692 | H14: =FLOOR((C14/2)*(G14/1000),0.01) -> 18.4 | I14: =(60*F14)/(3.14*(C14/1000)) -> 28.552603 | J14: 200 | K14: =ROUNDUP($F14/$C14*Bandgegevens!$P$14,3) -> 0.144 | L14: =IF(K14=0,"niet beschikbaar",ROUNDDOWN(D14/K14,0)) -> 381 | M14: =ROUNDUP($F14/$C14*Bandgegevens!$Q$14,3) -> 0.168 | N14: =IF(K14=0,"niet beschikbaar",ROUNDDOWN(D14/M14,0)) -> 327 | O14: =ROUNDUP($F14/$C14*Bandgegevens!$R$14,3) -> 0.157 | P14: =IF(K14=0,"niet beschikbaar",ROUNDDOWN(D14/O14,0)) -> 350 | Q14: 11 | R14: =IF(D14=INDEX('tech_specs TM'!T$4:T$20,$T$3),F14,"niet beschikbaar") -> niet beschikbaar | T14: 200
A15: PT86X Beta | B15: Procon | C15: 87 | D15: 55 | E15: 2 | F15: 0.16 | G15: =D15/F15 -> 343.75 | H15: =FLOOR((C15/2)*(G15/1000),0.01) -> 14.95 | I15: =(60*F15)/(3.14*(C15/1000)) -> 35.141665 | J15: 200 | K15: =ROUNDUP($F15/$C15*Bandgegevens!$P$14,3) -> 0.177 | L15: =IF(K15=0,"niet beschikbaar",ROUNDDOWN(D15/K15,0)) -> 310 | M15: =ROUNDUP($F15/$C15*Bandgegevens!$Q$14,3) -> 0.206 | N15: =IF(K15=0,"niet beschikbaar",ROUNDDOWN(D15/M15,0)) -> 266 | O15: =ROUNDUP($F15/$C15*Bandgegevens!$R$14,3) -> 0.194 | P15: =IF(K15=0,"niet beschikbaar",ROUNDDOWN(D15/O15,0)) -> 283 | Q15: 12 | R15: =IF(D15=INDEX('tech_specs TM'!T$4:T$20,$T$3),F15,"niet beschikbaar") -> niet beschikbaar | T15: 250
... A20: PT86X Beta | B20: Procon | C20: 87 | D20: 55 | E20: 2 | F20: 0.5 | G20: =D20/F20 -> 110 | H20: =FLOOR((C20/2)*(G20/1000),0.01) -> 4.78 | I20: =(60*F20)/(3.14*(C20/1000)) -> 109.8177 | J20: 200 | K20: =ROUNDUP($F20/$C20*Bandgegevens!$P$14,3) -> 0.552 | L20: =IF(K20=0,"niet beschikbaar",ROUNDDOWN(D20/K20,0)) -> 99 | M20: =ROUNDUP($F20/$C20*Bandgegevens!$Q$14,3) -> 0.644 | N20: =IF(K20=0,"niet beschikbaar",ROUNDDOWN(D20/M20,0)) -> 85 | O20: =ROUNDUP($F20/$C20*Bandgegevens!$R$14,3) -> 0.604 | P20: =IF(K20=0,"niet beschikbaar",ROUNDDOWN(D20/O20,0)) -> 91 | Q20: 17 | R20: =IF(D20=INDEX('tech_specs TM'!T$4:T$20,$T$3),F20,"niet beschikbaar") -> niet beschikbaar | T20: 750
A21: PT86X Beta | B21: Procon | C21: 87 | D21: 55 | E21: 2 | F21: 0.63 | G21: =D21/F21 -> 87.301587 | H21: =FLOOR((C21/2)*(G21/1000),0.01) -> 3.79 | I21: =(60*F21)/(3.14*(C21/1000)) -> 138.37031 | J21: 200 | K21: =ROUNDUP($F21/$C21*Bandgegevens!$P$14,3) -> 0.696 | L21: =IF(K21=0,"niet beschikbaar",ROUNDDOWN(D21/K21,0)) -> 79 | M21: =ROUNDUP($F21/$C21*Bandgegevens!$Q$14,3) -> 0.812 | N21: =IF(K21=0,"niet beschikbaar",ROUNDDOWN(D21/M21,0)) -> 67 | O21: =ROUNDUP($F21/$C21*Bandgegevens!$R$14,3) -> 0.761 | P21: =IF(K21=0,"niet beschikbaar",ROUNDDOWN(D21/O21,0)) -> 72 | Q21: 18 | R21: =IF(D21=INDEX('tech_specs TM'!T$4:T$20,$T$3),F21,"niet beschikbaar") -> niet beschikbaar
A22: PT86X Beta | B22: Procon | C22: 87 | D22: 55 | E22: 2 | F22: 0.8 | G22: =D22/F22 -> 68.75 | H22: =FLOOR((C22/2)*(G22/1000),0.01) -> 2.99 | I22: =(60*F22)/(3.14*(C22/1000)) -> 175.70832 | J22: 200 | K22: =ROUNDUP($F22/$C22*Bandgegevens!$P$14,3) -> 0.883 | L22: =IF(K22=0,"niet beschikbaar",ROUNDDOWN(D22/K22,0)) -> 62 | M22: =ROUNDUP($F22/$C22*Bandgegevens!$Q$14,3) -> 1.03 | N22: =IF(K22=0,"niet beschikbaar",ROUNDDOWN(D22/M22,0)) -> 53 | O22: =ROUNDUP($F22/$C22*Bandgegevens!$R$14,3) -> 0.966 | P22: =IF(K22=0,"niet beschikbaar",ROUNDDOWN(D22/O22,0)) -> 56 | Q22: 19 | R22: =IF(D22=INDEX('tech_specs TM'!T$4:T$20,$T$3),F22,"niet beschikbaar") -> niet beschikbaar
A23: PT86X Beta | B23: Procon | C23: 87 | D23: 55 | E23: 2 | F23: 1 | G23: =D23/F23 -> 55 | H23: =FLOOR((C23/2)*(G23/1000),0.01) -> 2.39 | I23: =(60*F23)/(3.14*(C23/1000)) -> 219.63541 | J23: 200 | K23: =ROUNDUP($F23/$C23*Bandgegevens!$P$14,3) -> 1.104 | L23: =IF(K23=0,"niet beschikbaar",ROUNDDOWN(D23/K23,0)) -> 49 | M23: =ROUNDUP($F23/$C23*Bandgegevens!$Q$14,3) -> 1.288 | N23: =IF(K23=0,"niet beschikbaar",ROUNDDOWN(D23/M23,0)) -> 42 | O23: =ROUNDUP($F23/$C23*Bandgegevens!$R$14,3) -> 1.207 | P23: =IF(K23=0,"niet beschikbaar",ROUNDDOWN(D23/O23,0)) -> 45 | Q23: 20 | R23: =IF(D23=INDEX('tech_specs TM'!T$4:T$20,$T$3),F23,"niet beschikbaar") -> niet beschikbaar
A24: PT87X Beta | B24: Procon | C24: 87 | D24: 20 | E24: 8 | F24: 0.033 | G24: =D24/F24 -> 606.06061 | H24: =FLOOR((C24/2)*(G24/1000),0.01) -> 26.36 | I24: =(60*F24)/(3.14*(C24/1000)) -> 7.2479684 | J24: 250 | K24: =ROUNDUP($F24/$C24*Bandgegevens!$P$14,3) -> 0.037 | L24: =IF(K24=0,"niet beschikbaar",ROUNDDOWN(D24/K24,0)) -> 540 | M24: =ROUNDUP($F24/$C24*Bandgegevens!$Q$14,3) -> 0.043 | N24: =IF(K24=0,"niet beschikbaar",ROUNDDOWN(D24/M24,0)) -> 465 | O24: =ROUNDUP($F24/$C24*Bandgegevens!$R$14,3) -> 0.04 | P24: =IF(K24=0,"niet beschikbaar",ROUNDDOWN(D24/O24,0)) -> 500 | Q24: 21 | R24: =IF(D24=INDEX('tech_specs TM'!T$4:T$20,$T$3),F24,"niet beschikbaar") -> niet beschikbaar
A25: PT87X Beta | B25: Procon | C25: 87 | D25: 20 | E25: 8 | F25: 0.04 | G25: =D25/F25 -> 500 | H25: =FLOOR((C25/2)*(G25/1000),0.01) -> 21.75 | I25: =(60*F25)/(3.14*(C25/1000)) -> 8.7854162 | J25: 250 | K25: =ROUNDUP($F25/$C25*Bandgegevens!$P$14,3) -> 0.045 | L25: =IF(K25=0,"niet beschikbaar",ROUNDDOWN(D25/K25,0)) -> 444 | M25: =ROUNDUP($F25/$C25*Bandgegevens!$Q$14,3) -> 0.052 | N25: =IF(K25=0,"niet beschikbaar",ROUNDDOWN(D25/M25,0)) -> 384 | O25: =ROUNDUP($F25/$C25*Bandgegevens!$R$14,3) -> 0.049 | P25: =IF(K25=0,"niet beschikbaar",ROUNDDOWN(D25/O25,0)) -> 408 | Q25: 22 | R25: =IF(D25=INDEX('tech_specs TM'!T$4:T$20,$T$3),F25,"niet beschikbaar") -> niet beschikbaar
A26: PT87X Beta | B26: Procon | C26: 87 | D26: 20 | E26: 8 | F26: 0.05 | G26: =D26/F26 -> 400 | H26: =FLOOR((C26/2)*(G26/1000),0.01) -> 17.4 | I26: =(60*F26)/(3.14*(C26/1000)) -> 10.98177 | J26: 250 | K26: =ROUNDUP($F26/$C26*Bandgegevens!$P$14,3) -> 0.056 | L26: =IF(K26=0,"niet beschikbaar",ROUNDDOWN(D26/K26,0)) -> 357 | M26: =ROUNDUP($F26/$C26*Bandgegevens!$Q$14,3) -> 0.065 | N26: =IF(K26=0,"niet beschikbaar",ROUNDDOWN(D26/M26,0)) -> 307 | O26: =ROUNDUP($F26/$C26*Bandgegevens!$R$14,3) -> 0.061 | P26: =IF(K26=0,"niet beschikbaar",ROUNDDOWN(D26/O26,0)) -> 327 | Q26: 23 | R26: =IF(D26=INDEX('tech_specs TM'!T$4:T$20,$T$3),F26,"niet beschikbaar") -> niet beschikbaar
A27: PT87X Beta | B27: Procon | C27: 87 | D27: 55 | E27: 4 | F27: 0.065 | G27: =D27/F27 -> 846.15385 | H27: =FLOOR((C27/2)*(G27/1000),0.01) -> 36.8 | I27: =(60*F27)/(3.14*(C27/1000)) -> 14.276301 | J27: 250 | K27: =ROUNDUP($F27/$C27*Bandgegevens!$P$14,3) -> 0.072 | L27: =IF(K27=0,"niet beschikbaar",ROUNDDOWN(D27/K27,0)) -> 763 | M27: =ROUNDUP($F27/$C27*Bandgegevens!$Q$14,3) -> 0.084 | N27: =IF(K27=0,"niet beschikbaar",ROUNDDOWN(D27/M27,0)) -> 654 | O27: =ROUNDUP($F27/$C27*Bandgegevens!$R$14,3) -> 0.079 | P27: =IF(K27=0,"niet beschikbaar",ROUNDDOWN(D27/O27,0)) -> 696 | Q27: 24 | R27: =IF(D27=INDEX('tech_specs TM'!T$4:T$20,$T$3),F27,"niet beschikbaar") -> niet beschikbaar
A28: PT87X Beta | B28: Procon | C28: 87 | D28: 55 | E28: 4 | F28: 0.08 | G28: =D28/F28 -> 687.5 | H28: =FLOOR((C28/2)*(G28/1000),0.01) -> 29.9 | I28: =(60*F28)/(3.14*(C28/1000)) -> 17.570832 | J28: 250 | K28: =ROUNDUP($F28/$C28*Bandgegevens!$P$14,3) -> 0.089 | L28: =IF(K28=0,"niet beschikbaar",ROUNDDOWN(D28/K28,0)) -> 617 | M28: =ROUNDUP($F28/$C28*Bandgegevens!$Q$14,3) -> 0.103 | N28: =IF(K28=0,"niet beschikbaar",ROUNDDOWN(D28/M28,0)) -> 533 | O28: =ROUNDUP($F28/$C28*Bandgegevens!$R$14,3) -> 0.097 | P28: =IF(K28=0,"niet beschikbaar",ROUNDDOWN(D28/O28,0)) -> 567 | Q28: 25 | R28: =IF(D28=INDEX('tech_specs TM'!T$4:T$20,$T$3),F28,"niet beschikbaar") -> niet beschikbaar
A29: PT87X Beta | B29: Procon | C29: 87 | D29: 55 | E29: 4 | F29: 0.1 | G29: =D29/F29 -> 550 | H29: =FLOOR((C29/2)*(G29/1000),0.01) -> 23.92 | I29: =(60*F29)/(3.14*(C29/1000)) -> 21.963541 | J29: 250 | K29: =ROUNDUP($F29/$C29*Bandgegevens!$P$14,3) -> 0.111 | L29: =IF(K29=0,"niet beschikbaar",ROUNDDOWN(D29/K29,0)) -> 495 | M29: =ROUNDUP($F29/$C29*Bandgegevens!$Q$14,3) -> 0.129 | N29: =IF(K29=0,"niet beschikbaar",ROUNDDOWN(D29/M29,0)) -> 426 | O29: =ROUNDUP($F29/$C29*Bandgegevens!$R$14,3) -> 0.121 | P29: =IF(K29=0,"niet beschikbaar",ROUNDDOWN(D29/O29,0)) -> 454 | Q29: 26 | R29: =IF(D29=INDEX('tech_specs TM'!T$4:T$20,$T$3),F29,"niet beschikbaar") -> niet beschikbaar
A30: PT87X Beta | B30: Procon | C30: 87 | D30: 55 | E30: 4 | F30: 0.125 | G30: =D30/F30 -> 440 | H30: =FLOOR((C30/2)*(G30/1000),0.01) -> 19.14 | I30: =(60*F30)/(3.14*(C30/1000)) -> 27.454426 | J30: 250 | K30: =ROUNDUP($F30/$C30*Bandgegevens!$P$14,3) -> 0.138 | L30: =IF(K30=0,"niet beschikbaar",ROUNDDOWN(D30/K30,0)) -> 398 | M30: =ROUNDUP($F30/$C30*Bandgegevens!$Q$14,3) -> 0.161 | N30: =IF(K30=0,"niet beschikbaar",ROUNDDOWN(D30/M30,0)) -> 341 | O30: =ROUNDUP($F30/$C30*Bandgegevens!$R$14,3) -> 0.151 | P30: =IF(K30=0,"niet beschikbaar",ROUNDDOWN(D30/O30,0)) -> 364 | Q30: 27 | R30: =IF(D30=INDEX('tech_specs TM'!T$4:T$20,$T$3),F30,"niet beschikbaar") -> niet beschikbaar
A31: PT87X Beta | B31: Procon | C31: 87 | D31: 55 | E31: 4 | F31: 0.16 | G31: =D31/F31 -> 343.75 | H31: =FLOOR((C31/2)*(G31/1000),0.01) -> 14.95 | I31: =(60*F31)/(3.14*(C31/1000)) -> 35.141665 | J31: 250 | K31: =ROUNDUP($F31/$C31*Bandgegevens!$P$14,3) -> 0.177 | L31: =IF(K31=0,"niet beschikbaar",ROUNDDOWN(D31/K31,0)) -> 310 | M31: =ROUNDUP($F31/$C31*Bandgegevens!$Q$14,3) -> 0.206 | N31: =IF(K31=0,"niet beschikbaar",ROUNDDOWN(D31/M31,0)) -> 266 | O31: =ROUNDUP($F31/$C31*Bandgegevens!$R$14,3) -> 0.194 | P31: =IF(K31=0,"niet beschikbaar",ROUNDDOWN(D31/O31,0)) -> 283 | Q31: 28 | R31: =IF(D31=INDEX('tech_specs TM'!T$4:T$20,$T$3),F31,"niet beschikbaar") -> niet beschikbaar
A32: PT87X Beta | B32: Procon | C32: 87 | D32: 55 | E32: 4 | F32: 0.2 | G32: =D32/F32 -> 275 | H32: =FLOOR((C32/2)*(G32/1000),0.01) -> 11.96 | I32: =(60*F32)/(3.14*(C32/1000)) -> 43.927081 | J32: 250 | K32: =ROUNDUP($F32/$C32*Bandgegevens!$P$14,3) -> 0.221 | L32: =IF(K32=0,"niet beschikbaar",ROUNDDOWN(D32/K32,0)) -> 248 | M32: =ROUNDUP($F32/$C32*Bandgegevens!$Q$14,3) -> 0.258 | N32: =IF(K32=0,"niet beschikbaar",ROUNDDOWN(D32/M32,0)) -> 213 | O32: =ROUNDUP($F32/$C32*Bandgegevens!$R$14,3) -> 0.242 | P32: =IF(K32=0,"niet beschikbaar",ROUNDDOWN(D32/O32,0)) -> 227 | Q32: 29 | R32: =IF(D32=INDEX('tech_specs TM'!T$4:T$20,$T$3),F32,"niet beschikbaar") -> niet beschikbaar
... A46: PT87X Beta | B46: Procon | C46: 87 | D46: 100 | E46: 2 | F46: 1 | G46: =D46/F46 -> 100 | H46: =FLOOR((C46/2)*(G46/1000),0.01) -> 4.35 | I46: =(60*F46)/(3.14*(C46/1000)) -> 219.63541 | J46: 250 | K46: =ROUNDUP($F46/$C46*Bandgegevens!$P$14,3) -> 1.104 | L46: =IF(K46=0,"niet beschikbaar",ROUNDDOWN(D46/K46,0)) -> 90 | M46: =ROUNDUP($F46/$C46*Bandgegevens!$Q$14,3) -> 1.288 | N46: =IF(K46=0,"niet beschikbaar",ROUNDDOWN(D46/M46,0)) -> 77 | O46: =ROUNDUP($F46/$C46*Bandgegevens!$R$14,3) -> 1.207 | P46: =IF(K46=0,"niet beschikbaar",ROUNDDOWN(D46/O46,0)) -> 82 | Q46: 43 | R46: =IF(D46=INDEX('tech_specs TM'!T$4:T$20,$T$3),F46,"niet beschikbaar") -> niet beschikbaar
A47: PT113X Beta | B47: Procon | C47: 113 | D47: 65 | E47: 8 | F47: 0.04 | G47: =D47/F47 -> 1625 | H47: =FLOOR((C47/2)*(G47/1000),0.01) -> 91.81 | I47: =(60*F47)/(3.14*(C47/1000)) -> 6.763993 | J47: 260 | K47: =ROUNDUP($F47/$C47*Bandgegevens!$W$14,3) -> 0.046 | L47: =ROUNDDOWN(D47/K47,0) -> 1413 | M47: =ROUNDUP($F47/C47*Bandgegevens!$X$14,3) -> 0.052 | N47: =ROUNDDOWN(D47/M47,0) -> 1250 | O47: =ROUNDUP($F47/$C47*Bandgegevens!$Y$14,3) -> 0.049 | P47: =ROUNDDOWN(D47/O47,0) -> 1326 | Q47: 44 | R47: =IF(D47=INDEX('tech_specs TM'!T$4:T$20,$T$3),F47,"niet beschikbaar") -> niet beschikbaar
A48: PT113X Beta | B48: Procon | C48: 113 | D48: 65 | E48: 8 | F48: 0.05 | G48: =D48/F48 -> 1300 | H48: =FLOOR((C48/2)*(G48/1000),0.01) -> 73.45 | I48: =(60*F48)/(3.14*(C48/1000)) -> 8.4549913 | J48: 260 | K48: =ROUNDUP($F48/$C48*Bandgegevens!$W$14,3) -> 0.058 | L48: =ROUNDDOWN(D48/K48,0) -> 1120 | M48: =ROUNDUP($F48/C48*Bandgegevens!$X$14,3) -> 0.065 | N48: =ROUNDDOWN(D48/M48,0) -> 1000 | O48: =ROUNDUP($F48/$C48*Bandgegevens!$Y$14,3) -> 0.062 | P48: =ROUNDDOWN(D48/O48,0) -> 1048 | Q48: 45 | R48: =IF(D48=INDEX('tech_specs TM'!T$4:T$20,$T$3),F48,"niet beschikbaar") -> niet beschikbaar
A49: PT113X Beta | B49: Procon | C49: 113 | D49: 65 | E49: 8 | F49: 0.063 | G49: =D49/F49 -> 1031.746 | H49: =FLOOR((C49/2)*(G49/1000),0.01) -> 58.29 | I49: =(60*F49)/(3.14*(C49/1000)) -> 10.653289 | J49: 260 | K49: =ROUNDUP($F49/$C49*Bandgegevens!$W$14,3) -> 0.072 | L49: =ROUNDDOWN(D49/K49,0) -> 902 | M49: =ROUNDUP($F49/C49*Bandgegevens!$X$14,3) -> 0.082 | N49: =ROUNDDOWN(D49/M49,0) -> 792 | O49: =ROUNDUP($F49/$C49*Bandgegevens!$Y$14,3) -> 0.077 | P49: =ROUNDDOWN(D49/O49,0) -> 844 | Q49: 46 | R49: =IF(D49=INDEX('tech_specs TM'!T$4:T$20,$T$3),F49,"niet beschikbaar") -> niet beschikbaar
A50: PT113X Beta | B50: Procon | C50: 113 | D50: 65 | E50: 8 | F50: 0.08 | G50: =D50/F50 -> 812.5 | H50: =FLOOR((C50/2)*(G50/1000),0.01) -> 45.9 | I50: =(60*F50)/(3.14*(C50/1000)) -> 13.527986 | J50: 260 | K50: =ROUNDUP($F50/$C50*Bandgegevens!$W$14,3) -> 0.092 | L50: =ROUNDDOWN(D50/K50,0) -> 706 | M50: =ROUNDUP($F50/C50*Bandgegevens!$X$14,3) -> 0.104 | N50: =ROUNDDOWN(D50/M50,0) -> 625 | O50: =ROUNDUP($F50/$C50*Bandgegevens!$Y$14,3) -> 0.098 | P50: =ROUNDDOWN(D50/O50,0) -> 663 | Q50: 47 | R50: =IF(D50=INDEX('tech_specs TM'!T$4:T$20,$T$3),F50,"niet beschikbaar") -> niet beschikbaar
A51: PT113X Beta | B51: Procon | C51: 113 | D51: 65 | E51: 8 | F51: 0.1 | G51: =D51/F51 -> 650 | H51: =FLOOR((C51/2)*(G51/1000),0.01) -> 36.72 | I51: =(60*F51)/(3.14*(C51/1000)) -> 16.909983 | J51: 260 | K51: =ROUNDUP($F51/$C51*Bandgegevens!$W$14,3) -> 0.115 | L51: =ROUNDDOWN(D51/K51,0) -> 565 | M51: =ROUNDUP($F51/C51*Bandgegevens!$X$14,3) -> 0.13 | N51: =ROUNDDOWN(D51/M51,0) -> 500 | O51: =ROUNDUP($F51/$C51*Bandgegevens!$Y$14,3) -> 0.123 | P51: =ROUNDDOWN(D51/O51,0) -> 528 | Q51: 48 | R51: =IF(D51=INDEX('tech_specs TM'!T$4:T$20,$T$3),F51,"niet beschikbaar") -> niet beschikbaar
A52: PT113X Beta | B52: Procon | C52: 113 | D52: 65 | E52: 8 | F52: 0.125 | G52: =D52/F52 -> 520 | H52: =FLOOR((C52/2)*(G52/1000),0.01) -> 29.38 | I52: =(60*F52)/(3.14*(C52/1000)) -> 21.137478 | J52: 260 | K52: =ROUNDUP($F52/$C52*Bandgegevens!$W$14,3) -> 0.143 | L52: =ROUNDDOWN(D52/K52,0) -> 454 | M52: =ROUNDUP($F52/C52*Bandgegevens!$X$14,3) -> 0.162 | N52: =ROUNDDOWN(D52/M52,0) -> 401 | O52: =ROUNDUP($F52/$C52*Bandgegevens!$Y$14,3) -> 0.153 | P52: =ROUNDDOWN(D52/O52,0) -> 424 | Q52: 49 | R52: =IF(D52=INDEX('tech_specs TM'!T$4:T$20,$T$3),F52,"niet beschikbaar") -> niet beschikbaar
A53: PT113X Beta | B53: Procon | C53: 113 | D53: 65 | E53: 8 | F53: 0.16 | G53: =D53/F53 -> 406.25 | H53: =FLOOR((C53/2)*(G53/1000),0.01) -> 22.95 | I53: =(60*F53)/(3.14*(C53/1000)) -> 27.055972 | J53: 260 | K53: =ROUNDUP($F53/$C53*Bandgegevens!$W$14,3) -> 0.183 | L53: =ROUNDDOWN(D53/K53,0) -> 355 | M53: =ROUNDUP($F53/C53*Bandgegevens!$X$14,3) -> 0.207 | N53: =ROUNDDOWN(D53/M53,0) -> 314 | O53: =ROUNDUP($F53/$C53*Bandgegevens!$Y$14,3) -> 0.196 | P53: =ROUNDDOWN(D53/O53,0) -> 331 | Q53: 50 | R53: =IF(D53=INDEX('tech_specs TM'!T$4:T$20,$T$3),F53,"niet beschikbaar") -> niet beschikbaar
A54: PT113X Beta | B54: Procon | C54: 113 | D54: 65 | E54: 8 | F54: 0.2 | G54: =D54/F54 -> 325 | H54: =FLOOR((C54/2)*(G54/1000),0.01) -> 18.36 | I54: =(60*F54)/(3.14*(C54/1000)) -> 33.819965 | J54: 260 | K54: =ROUNDUP($F54/$C54*Bandgegevens!$W$14,3) -> 0.229 | L54: =ROUNDDOWN(D54/K54,0) -> 283 | M54: =ROUNDUP($F54/C54*Bandgegevens!$X$14,3) -> 0.259 | N54: =ROUNDDOWN(D54/M54,0) -> 250 | O54: =ROUNDUP($F54/$C54*Bandgegevens!$Y$14,3) -> 0.245 | P54: =ROUNDDOWN(D54/O54,0) -> 265 | Q54: 51 | R54: =IF(D54=INDEX('tech_specs TM'!T$4:T$20,$T$3),F54,"niet beschikbaar") -> niet beschikbaar
A55: PT113X Beta | B55: Procon | C55: 113 | D55: 65 | E55: 8 | F55: 0.25 | G55: =D55/F55 -> 260 | H55: =FLOOR((C55/2)*(G55/1000),0.01) -> 14.69 | I55: =(60*F55)/(3.14*(C55/1000)) -> 42.274956 | J55: 260 | K55: =ROUNDUP($F55/$C55*Bandgegevens!$W$14,3) -> 0.286 | L55: =ROUNDDOWN(D55/K55,0) -> 227 | M55: =ROUNDUP($F55/C55*Bandgegevens!$X$14,3) -> 0.324 | N55: =ROUNDDOWN(D55/M55,0) -> 200 | O55: =ROUNDUP($F55/$C55*Bandgegevens!$Y$14,3) -> 0.306 | P55: =ROUNDDOWN(D55/O55,0) -> 212 | Q55: 52 | R55: =IF(D55=INDEX('tech_specs TM'!T$4:T$20,$T$3),F55,"niet beschikbaar") -> niet beschikbaar
A56: PT113X Beta | B56: Procon | C56: 113 | D56: 65 | E56: 8 | F56: 0.32 | G56: =D56/F56 -> 203.125 | H56: =FLOOR((C56/2)*(G56/1000),0.01) -> 11.47 | I56: =(60*F56)/(3.14*(C56/1000)) -> 54.111944 | J56: 260 | K56: =ROUNDUP($F56/$C56*Bandgegevens!$W$14,3) -> 0.366 | L56: =ROUNDDOWN(D56/K56,0) -> 177 | M56: =ROUNDUP($F56/C56*Bandgegevens!$X$14,3) -> 0.414 | N56: =ROUNDDOWN(D56/M56,0) -> 157 | O56: =ROUNDUP($F56/$C56*Bandgegevens!$Y$14,3) -> 0.391 | P56: =ROUNDDOWN(D56/O56,0) -> 166 | Q56: 53 | R56: =IF(D56=INDEX('tech_specs TM'!T$4:T$20,$T$3),F56,"niet beschikbaar") -> niet beschikbaar
A57: PT113X Beta | B57: Procon | C57: 113 | D57: 80 | E57: 6 | F57: 0.053 | G57: =D57/F57 -> 1509.434 | H57: =FLOOR((C57/2)*(G57/1000),0.01) -> 85.28 | I57: =(60*F57)/(3.14*(C57/1000)) -> 8.9622907 | J57: 260 | K57: =ROUNDUP($F57/$C57*Bandgegevens!$W$14,3) -> 0.061 | L57: =ROUNDDOWN(D57/K57,0) -> 1311 | M57: =ROUNDUP($F57/C57*Bandgegevens!$X$14,3) -> 0.069 | N57: =ROUNDDOWN(D57/M57,0) -> 1159 | O57: =ROUNDUP($F57/$C57*Bandgegevens!$Y$14,3) -> 0.065 | P57: =ROUNDDOWN(D57/O57,0) -> 1230 | Q57: 54 | R57: =IF(D57=INDEX('tech_specs TM'!T$4:T$20,$T$3),F57,"niet beschikbaar") -> niet beschikbaar
A58: PT113X Beta | B58: Procon | C58: 113 | D58: 80 | E58: 6 | F58: 0.067 | G58: =D58/F58 -> 1194.0299 | H58: =FLOOR((C58/2)*(G58/1000),0.01) -> 67.46 | I58: =(60*F58)/(3.14*(C58/1000)) -> 11.329688 | J58: 260 | K58: =ROUNDUP($F58/$C58*Bandgegevens!$W$14,3) -> 0.077 | L58: =ROUNDDOWN(D58/K58,0) -> 1038 | M58: =ROUNDUP($F58/C58*Bandgegevens!$X$14,3) -> 0.087 | N58: =ROUNDDOWN(D58/M58,0) -> 919 | O58: =ROUNDUP($F58/$C58*Bandgegevens!$Y$14,3) -> 0.082 | P58: =ROUNDDOWN(D58/O58,0) -> 975 | Q58: 55 | R58: =IF(D58=INDEX('tech_specs TM'!T$4:T$20,$T$3),F58,"niet beschikbaar") -> niet beschikbaar
...

Sheet Uitv_tm
B2: Elektrische aanlsuiting opties: | D2: Afbeelding:
B4: T1 Rechte wartel | D4: #VALUE!
B5: T4 klemmenkast RVS | D5: #VALUE!
B6: T5 Haakse wartel RVS | D6: #VALUE!
B7: 3
B8: =INDEX(B3:B6,B7) -> T4 klemmenkast RVS | D8: =INDEX(D3:D6,D7) -> #VALUE!

Sheet Bandgegevens
C3: Banden Ammeraal serie AmmDrive: | L3: PT 87 | S3: PT113 | Z3: PT138
C4: Type band | D4: Steek [mm] | E4: Dikte tand [mm] | F4: Dikte band [mm] | G4: Wrijvingscoeff RVS droog | H4: Wrijvingscoeff RVS nat | I4: Wrijvingscoeff HDPE droog | J4: Wrijvingscoeff HDPE nat | K4: Min afstand sprocket/pulley | L4: Diameter nominaal | M4: RVS mantel Z = | N4: Sprocket Z = | O4: Bekleding Z = | P4: RVS mantel PCD = | Q4: Sprocket PCD = | R4: Bekleding PCD = | S4: Diameter nominaal | T4: RVS mantel Z = | U4: Sprocket Z = | V4: Bekleding Z = | W4: RVS mantel PCD = | X4: Sprocket PCD = | Y4: Bekleding PCD = | Z4: Diameter nominaal | AA4: RVS mantel Z = | AB4: Sprocket Z = | AC4: Bekleding Z = | AD4: RVS mantel PCD = | AE4: Sprocket PCD = | AF4: Bekleding PCD =
C5: Soliflex Pro mini 1,5 | D5: 25.5 | E5: 4.5 | F5: 1.5 | G5: 0.55 | H5: 0.4 | I5: 0.35 | J5: 0.38 | K5: 150 | L5: 87 | M5: 12 | N5: 14 | O5: 13 | P5: 96 | Q5: 112 | R5: 105 | S5: 113 | T5: 16 | U5: 18 | V5: 17 | W5: 129 | X5: 146 | Y5: 138 | Z5: 138 | AA5: 18 | AB5: 20 | AC5: 19 | AD5: 145 | AE5: 162 | AF5: 154
C6: Soliflex Pro mini 2,0 | D6: 25.5 | E6: 4.5 | F6: 2 | G6: 0.55 | H6: 0.4 | I6: 0.35 | J6: 0.38 | K6: 150 | L6: 87 | M6: 12 | N6: 14 | O6: 13 | P6: 96 | Q6: 112 | R6: 105 | S6: 113 | T6: 16 | U6: 18 | V6: 17 | W6: 129 | X6: 146 | Y6: 138 | Z6: 138 | AA6: 18 | AB6: 20 | AC6: 19 | AD6: 145 | AE6: 162 | AF6: 154
C7: Soliflex Pro 2,0 | D7: 51 | E7: 8.5 | F7: 2 | G7: 0.55 | H7: 0.4 | I7: 0.35 | J7: 0.38 | K7: 150 | L7: 87 | M7: #nb | N7: 7 | O7: 7 | P7: 0 | Q7: 113 | R7: 113 | S7: 113 | T7: 8 | U7: 10 | V7: 9 | W7: 130 | X7: 162 | Y7: 146 | Z7: 138 | AA7: 10 | AB7: 12 | AC7: 10 | AD7: 162 | AE7: 195 | AF7: 162
C8: Soliflex Pro 3,0 | D8: 51 | E8: 8.5 | F8: 3 | G8: 0.55 | H8: 0.4 | I8: 0.35 | J8: 0.38 | K8: 150 | L8: 87 | M8: #nb | N8: 7 | O8: 7 | P8: 0 | Q8: 113 | R8: 113 | S8: 113 | T8: 8 | U8: 10 | V8: 9 | W8: 130 | X8: 162 | Y8: 146 | Z8: 138 | AA8: 10 | AB8: 12 | AC8: 10 | AD8: 162 | AE8: 195 | AF8: 162
C9: Soliflex Pro 4,0 | D9: 51 | E9: 8.5 | F9: 4 | G9: 0.55 | H9: 0.4 | I9: 0.35 | J9: 0.38 | K9: 150 | L9: 87 | M9: #nb | N9: 7 | O9: 7 | P9: 0 | Q9: 113 | R9: 113 | S9: 113 | T9: 8 | U9: 10 | V9: 9 | W9: 130 | X9: 162 | Y9: 146 | Z9: 138 | AA9: 10 | AB9: 12 | AC9: 10 | AD9: 162 | AE9: 195 | AF9: 162
C10: Soliflex Full Bar mini | D10: 25.9 | E10: 3.6 | F10: 2.8 | G10: 0.55 | H10: 0.4 | I10: 0.35 | J10: 0.38 | K10: 150 | L10: 87 | M10: 12 | N10: 14 | O10: 13 | P10: 97 | Q10: 113 | R10: 105 | S10: 113 | T10: 15 | U10: 17 | V10: 16 | W10: 124 | X10: 137.5 | Y10: 129 | Z10: 138 | AA10: 18 | AB10: 20 | AC10: 19 | AD10: 145.6 | AE10: 162 | AF10: 154
C11: Soliflex Full Bar | D11: 48.9 | E11: 4.5 | F11: 3.3 | G11: 0.55 | H11: 0.4 | I11: 0.35 | J11: 0.38 | K11: 150 | L11: 87 | M11: #nb | N11: 7 | O11: 0 | P11: 0 | Q11: 111 | R11: 0 | S11: 113 | T11: 8 | U11: 9 | V11: 8 | W11: 125 | X11: 140 | Y11: 125 | Z11: 138 | AA11: 10 | AB11: 11 | AC11: 10 | AD11: 156 | AE11: 171 | AF11: 156
C12: Soliflex Center bar | D12: 39.5 | E12: 7.5 | F12: 3 | G12: 0.55 | H12: 0.4 | I12: 0.35 | J12: 0.38 | K12: 150 | L12: 87 | M12: #nb | N12: 9 | O12: 9 | P12: 0 | Q12: 113 | R12: 113 | S12: 113 | T12: 10 | U12: 11 | V12: 11 | W12: 126 | X12: 139 | Y12: 139 | Z12: 138 | AA12: 12 | AB12: 14 | AC12: 13 | AD12: 151 | AE12: 176 | AF12: 164
C13: 2
C14: =INDEX(C4:C12,$C$13) -> Soliflex Pro mini 1,5 | D14: =INDEX(D4:D12,$C$13) -> 25.5 | E14: =INDEX(E4:E12,$C$13) -> 4.5 | F14: =INDEX(F4:F12,$C$13) -> 1.5 | G14: =INDEX(G4:G12,$C$13) -> 0.55 | H14: =INDEX(H4:H12,$C$13) -> 0.4 | I14: =INDEX(I4:I12,$C$13) -> 0.35 | J14: =INDEX(J4:J12,$C$13) -> 0.38 | ... AF14: =INDEX(AF4:AF12,$C$13) -> 154
C18: Type conveyor | D18: opvoer hoek | E18: Opvoer hoogte:
C19: vlak, horizontaal | D19: 0
C20: vlak, opvoer | D20: : | E20: :
C21: knik band
C22: Zwanenhals
C23: 2
C24: =INDEX(C19:C22,$C$23) -> vlak, opvoer | D24: =INDEX(D19:D22,$C$23) -> : | E24: =INDEX(E19:E22,$C$23) -> : | F24: =INDEX(F19:F22,$C$23) -> 0 | G24: =INDEX(G19:G22,$C$23) -> 0 | H24: =INDEX(H19:H22,$C$23) -> 0
C27: Band ondersteuning
C28: Rollen
C29: RVS plaat, droog
C30: RVS plaat, nat
C31: HDPE droog
C32: HDPE nat
C33: onbekend
C35: Aandrijfmethode:
C36: RVS mantel
C37: Sprocket
C38: Bekleding
C39: 4
C40: =INDEX(C35:C38,$C$39) -> Bekleding | D40: =INDEX(D35:D38,$C$23) -> 0 | E40: =INDEX(E35:E38,$C$23) -> 0 | F40: =INDEX(F35:F38,$C$23) -> 0 | G40: =INDEX(G35:G38,$C$23) -> 0 | H40: =INDEX(H35:H38,$C$23) -> 0

Sheet Blad1
A1: Rulmeca | B1: TM080LS | C1: 81.5 | D1: 35 | E1: 4 | F1: 200 | G1: 0.11
A2: Rulmeca | B2: TM080LS | C2: 81.5 | D2: 35 | E2: 4 | F2: 200 | G2: 0.14
A3: Rulmeca | B3: TM080LS | C3: 81.5 | D3: 35 | E3: 4 | F3: 200 | G3: 0.18
A4: Rulmeca | B4: TM080LS | C4: 81.5 | D4: 35 | E4: 4 | F4: 200 | G4: 0.25
A5: Rulmeca | B5: TM080LS DER | C5: 81.5 | D5: 60 | E5: 4 | F5: 250 | G5: 0.11
A6: Rulmeca | B6: TM080LS DER | C6: 81.5 | D6: 60 | E6: 4 | F6: 250 | G6: 0.15
A7: Rulmeca | B7: TM080LS DER | C7: 81.5 | D7: 60 | E7: 4 | F7: 250 | G7: 0.19
A8: Rulmeca | B8: TM080LS DER | C8: 81.5 | D8: 60 | E8: 4 | F8: 250 | G8: 0.28
A9: Rulmeca | B9: TM080LS DER | C9: 81.5 | D9: 60 | E9: 4 | F9: 250 | G9: 0.39
A10: Rulmeca | B10: TM080LS DER | C10: 81.5 | D10: 60 | E10: 4 | F10: 250 | G10: 0.48
A11: Rulmeca | B11: TM080LS DER | C11: 81.5 | D11: 60 | E11: 2 | F11: 200 | G11: 0.21
A12: Rulmeca | B12: TM080LS DER | C12: 81.5 | D12: 60 | E12: 2 | F12: 200 | G12: 0.31
... A286: Rulmeca | B286: TM165LS | C286: 165 | D286: 2200 | E286: 2 | F286: 430 | G286: 3.15
